# 老王Python学习笔记
> 运行环境：代码编辑器sublime text 3（配置anaconda，python3.5）
## 二、进阶篇

## 进阶篇16-异常处理1.2

### 1.异常的几点注意
> 一个try就有一个except

1.1 慎用异常，不可滥用异常： 
- 1. 找到python的内置异常
> - LookupError(包含IndexError, KeyError), 
>- SyntaxError(包含IndetationError等), 
>- AssertionError, IOError, AttributeError等
- 2. 理解python的内置异常分别对应什么情况
- 3. 阅读你的代码，找到你的代码里可能会抛出内置异常的地方
- 4. 仅对这几行代码做异常处理

假设你无法知道代码会抛出什么异常，那么你的异常处理便是无效的。--> 准确了解你的代码情况。

#### 1.2 不要一个代码块，用try包围起来就完事。

#### 1.3 好吧，想try all exception？sys.exc_info()

```
# coding=utf-8

import sys

try:
    assert (1 + 1) > 2, 'error is coming'
except:
    exc = sys.exc_info()
    print(exc)
>>>(<class 'AssertionError'>, AssertionError('error is coming',), 
<traceback object at 0x0000000000A828C8>)
```

#### 1.4 logging如何使用呢

```
# first example 
import logging   

logger = logging.getLogger()

logfile = 'test.log'
hdlr = logging.FileHandler('sendlog.txt')

formatter = logging.Formatter('%(asctime)s %(levelname)s %(message)s')

hdlr.setFormatter(formatter)

logger.addHandler(hdlr)

logger.setLevel(logging.NOTSET)

# second example
import logging
# 配制根记录器（root logger）
logging.basicConfig(filename='url.log', format='%(levelname)-5s %(asctime)s %(message)s', level=logging.ERROR)
log = logging.getLogger('url')  # 创建logger对象
log.error(u"webpages can't be open: %s", url)  # 向logger发送ERROR日志消息

```

### 2.断言，一种开发期时检定代码的方式
只断言绝对不能出现的错误 

许多程序员都提倡：
> 先断言绝对不能发生的错误
然后，再去处理错误 （异常）

断言格式：

assert  表达式, "出错以后抛出的message"

```
assert expression == a, 'error is coming'

```

### 3.代码友好，自动处理垃圾,with.
### 4.自己定义异常？继承exception类。
下节课

---

## 习题：

1 定义一个函数func(filename) filename:为文件名，用with实现打开文件，并且输出文件内容。

```
# coding=utf-8
import os

def func1(filename):
    "filename:为文件名，用with实现打开文件，并且输出文件内容"
    if not os.path.isfile(filename):
        return '输入文件路径不合法'
    with open(filename, 'r') as f:
        return f.read()

print(func1(r"C:\Program Files\Sublime Text 3\practice\url.log"))
>>>
ERROR 2017-05-27 23:36:32,865 webpages can't be open: http://www.abc.com
ERROR 2017-05-28 23:12:45,409 webpages can't be open: http://www.abc.com
```
---

2 定好一个函数func(listinfo) listinfo:为列表，listinfo=[133,88,33,22,44,11,44,55,33,22,11,11,444,66,555] 返回一个列表包含小于100的偶数，并且用assert来断言
返回结果和类型。

```
def func2(listinfo):
    """
    listinfo:为列表，listinfo=[133,88,33,22,44,11,44,55,33,22,11,11,444,66,555]
    返回一个列表包含小于100的偶数，并且用assert来断言返回结果和类型。
    """

    if not isinstance(listinfo, list):
        return "输入对象类型错误"
    list1 = [x for x in listinfo if x < 100]
    list2 = [x for x in list1 if x % 2 == 0]
    return list2


listinfo = [133, 88, 33, 22, 44, 11, 44, 55, 33, 22, 11, 11, 444, 66, 555]
assert type(func2(listinfo)) == list
assert func2(func2(listinfo)) == [88, 22, 44, 44, 22, 66]
```
---

3 自己定义一个异常类，继承Exception类, 捕获下面的过程：判断raw_input()输入的字符串长度是否小于5，如果小于5，比如输入长度为3则输出:" The input is of length 3,expecting at least 5'，大于5输出"print success'

```
# first method
class lenclass(Exception):
    """
    定义一个异常类，继承Exception类,
    捕获下面的过程：判断raw_input()输入的字符串长度是否小于5，
    如果小于5，比如输入长度为3则输出:" The input is of length 3,expecting at least 5'
    大于5输出"print success'
    """

    def __init__(self, arg):
        super(lenclass, self).__init__()
        self.arg = arg

    def length(self):
        length = len(self.arg)
        if length < 5:
            return 'The input is of length %d,expecting at least 5' % length
        else:
            return 'print success'


s = input('please input a string: ')
lenc = lenclass(s)
print(lenc.length())

# python3.5运行结果
please input a string: zsx(input)
output: The input is of length 3,expecting at least 5

please input a string: zsxabc(input)
output: print success

```
---
```
# second method
# coding=utf-8

class myException(Exception):
    """
    定义一个异常类，继承Exception类,
    捕获下面的过程：判断raw_input()输入的字符串长度是否小于5，
    如果小于5，比如输入长度为3则输出:" The input is of length 3,expecting at least 5'
    大于5输出"print success'
    """

    def __init__(self, arg):
        self.arg = arg

    def length(self):
        length = len(self.arg)
        if length < 5:
            return 'The input is of length %d,expecting at least 5' % length
        else:
            return 'print success'


try:
    m = myException('input argument here')
except Exception as e:
    print(e)
else:
    print(m.length())

>>> print success
```






